Workbook

Sheet 7B Breakdown
A1: Llama 2 7B — Trainable Parameters, Stage by Stage
A2: Real published architecture config. Every value below is a live formula — change the inputs and everything recomputes.
A4: MODEL CONFIGURATION (inputs — edit these)
A5: Parameter | B5: Value | C5: Meaning
A6: hidden_size | B6: 4096 | C6: width of every token's vector (d_model)
A7: n_layers | B7: 32 | C7: number of stacked transformer layers
A8: n_heads | B8: 32 | C8: number of parallel attention heads
A9: head_dim | B9: =B6/B8 | C9: hidden_size / n_heads
A10: intermediate_size | B10: 11008 | C10: FFN's internal expanded width
A11: vocab_size | B11: 32000 | C11: number of distinct tokens the model knows
A13: STAGE 1 — INSIDE ONE LAYER (of the 32)
A14: Component | B14: Shape | C14: Formula (Excel) | D14: Parameters
A15: Attention (Q, K, V, O projections) | B15: [4 × hidden × hidden] | C15: 4 × hidden × hidden | D15: =4*$B$6*$B$6
A16: FFN (SwiGLU: gate_proj, up_proj, down_proj) | B16: [3 × hidden × intermediate] | C16: 3 × hidden × intermediate | D16: =3*$B$6*$B$10
A17: Norms (2× RMSNorm scale vectors) | B17: [2 × hidden] | C17: 2 × hidden | D17: =2*$B$6
A18: ONE LAYER — TOTAL | B18: attention + FFN + norms | C18: =SUM(D15:D17) | D18: =SUM(D15:D17)
A20: STAGE 2 — FULL MODEL (the addition, running total)
A21: Component | B21: Shape | C21: This stage | D21: Running total
A22: Token Embedding | B22: [vocab × hidden] | C22: =$B$11*$B$6 | D22: =C22
A23: All 32 Layers (n_layers × one-layer-total) | B23: [n_layers × 202,383,360] | C23: =$B$7*D18 | D23: =D23+C23
A24: Final Norm | B24: [hidden] | C24: =$B$6 | D24: =D24+C24
A25: Output Head (LM head, untied from input embedding) | B25: [vocab × hidden] | C25: =$B$11*$B$6 | D25: =D25+C25
A26: TOTAL TRAINABLE PARAMETERS | B26: embedding + layers + norm + head | C26: =SUM(C22:C25) | D26: =D25
A27: → in billions | C27: =C26/1000000000
A29: WHERE THE PARAMETERS ACTUALLY LIVE (% of total)
A30: Component | B30: Parameters | C30: % of total
A31: FFN (all 32 layers) | B31: =$B$7*D16 | C31: =B31/$C$26
A32: Attention (all 32 layers) | B32: =$B$7*D15 | C32: =B32/$C$26
A33: Embeddings (input + output head) | B33: =C22+C25 | C33: =B33/$C$26

Sheet 13B Cross-check
A1: Llama 2 13B — Same Formula, Different Model
A2: Identical structure to the 7B sheet. If the total below independently lands near 13B, the formula is confirmed, not tuned to one example.
A4: MODEL CONFIGURATION (real published values)
A5: Parameter | B5: Value | C5: Meaning
A6: hidden_size | B6: 5120
A7: n_layers | B7: 40
A8: n_heads | B8: 40
A9: head_dim | B9: =B6/B8
A10: intermediate_size | B10: 13824
A11: vocab_size | B11: 32000
A13: STAGE 1 — INSIDE ONE LAYER
A14: Component | B14: Shape | C14: Formula (Excel) | D14: Parameters
A15: Attention (Q, K, V, O) | B15: [4 × hidden × hidden] | C15: 4 × hidden × hidden | D15: =4*$B$6*$B$6
A16: FFN (SwiGLU) | B16: [3 × hidden × intermediate] | C16: 3 × hidden × intermediate | D16: =3*$B$6*$B$10
A17: Norms | B17: [2 × hidden] | C17: 2 × hidden | D17: =2*$B$6
A18: ONE LAYER — TOTAL | C18: =SUM(D15:D17) | D18: =SUM(D15:D17)
A20: STAGE 2 — FULL MODEL (the addition, running total)
A21: Component | B21: Shape | C21: This stage | D21: Running total
A22: Token Embedding | B22: [vocab × hidden] | C22: =$B$11*$B$6 | D22: =C22
A23: All 40 Layers | B23: [n_layers × one-layer-total] | C23: =$B$7*D18 | D23: =D23+C23
A24: Final Norm | B24: [hidden] | C24: =$B$6 | D24: =D24+C24
A25: Output Head | B25: [vocab × hidden] | C25: =$B$11*$B$6 | D25: =D25+C25
A26: TOTAL TRAINABLE PARAMETERS | C26: =SUM(C22:C25) | D26: =D25
A27: → in billions | C27: =C26/1000000000

Sheet Tokens & Scaling
A1: Parameters vs. Training Tokens — Chinchilla Scaling
A2: Live reference to the 7B Breakdown sheet's total.
A4: CHINCHILLA COMPUTE-OPTIMAL TOKEN COUNT
A5: Quantity | B5: Value | C5: Formula
A6: 7B model total parameters (N) | B6: ='7B Breakdown'!C26 | C6: from '7B Breakdown' sheet
A7: Chinchilla-optimal tokens (D ≈ 20 × N) | B7: =20*B6 | C7: 20 × N
A8: Real published Llama 2 7B training tokens | B8: 2000000000000 | C8: 2 trillion, from the Llama 2 paper
A9: Actual tokens-per-parameter ratio | B9: =B8/B6
A10: How far beyond Chinchilla-optimal | B10: =B8/B7
A12: Why: Chinchilla's D≈20N minimizes TRAINING compute for a target loss. It says nothing about INFERENCE cost. A smaller model trained far past the Chinchilla point can match a larger Chinchilla-optimal model's quality while being far cheaper to serve at inference time, forever, for every query — and inference cost dominates a deployed model's real lifetime cost.

Sheet Notes & Caveats
A1: Notes & Caveats
A3: SOURCE
A4: All configuration numbers (hidden_size, n_layers, n_heads, intermediate_size, vocab_size) are Meta's real published Llama 2 config values — not estimates.
A7: WHY THE FORMULA WORKS FOR 7B AND 13B
A8: Both use standard multi-head attention: every query head has its own key/value head, so Q, K, V, and O are all full [hidden × hidden] matrices — exactly what 4×hidden² assumes.
A11: WHY IT DOESN'T WORK FOR 70B
A12: Llama 2 70B uses grouped-query attention (GQA): multiple query heads share a smaller number of key/value heads, so K and V are smaller than [hidden × hidden]. Applying this sheet's formula to 70B's config overcounts by roughly 14% (≈78.4B computed vs. the real ≈68.9B). A correct GQA formula needs separate, smaller terms for K and V.
A15: WHY SWIGLU'S INTERMEDIATE SIZE IS ≈2.688× HIDDEN, NOT 4×
A16: A classic 2-matrix GELU FFN (up + down) at the standard 4× multiplier costs 2×hidden×(4×hidden) = 8×hidden² parameters. SwiGLU uses 3 matrices (gate, up, down) instead of 2 — solving 3×hidden×intermediate = 8×hidden² for intermediate gives (8/3)×hidden ≈ 2.667×hidden. For hidden=4096 that's ≈10,923 — and the real published intermediate_size, 11,008, is that exact target rounded up to the nearest multiple of 256 (11,008 / 256 = 43 exactly), for hardware efficiency.
A19: EMBEDDING TYING
A20: Llama does NOT tie the input token embedding and the output LM head — they are two separate [vocab × hidden] matrices, both counted separately in this sheet. Some other model families (e.g. GPT-2) DO tie them, which would remove one entire [vocab × hidden] term from the total.

Sheet Grassroots — All Layers & Heads
A1: Grassroots — Real Shapes, Every Layer, Every Head
A2: Real Llama 2 7B dimensions throughout (32,000 vocab, not a toy example). Every row shows the real matrix SHAPE and the parameter-count FORMULA it implies, summed until it IS the 7B total — not compressed with a ×32 shortcut. Column E explains WHY each row is shaped the way it is.
A4: MODEL DIMENSIONS (linked live to the '7B Breakdown' sheet — change it there, this sheet follows)
A5: Parameter | B5: Value | E5: Why
A6: vocab_size (initial tokens) | B6: ='7B Breakdown'!B11 | E6: This is the size of the tokenizer's vocabulary — the fixed list of sub-word pieces (like "ing", "the", "phot"+"o") the model can ever read or write. Every input token must be one of these 32,000 IDs. Picking this number is a trade-off made BEFORE the model is trained, by whoever built the tokenizer: too few tokens and every word gets chopped into many small pieces (longer sequences, more compute per sentence); too many tokens and the embedding table below gets enormous for diminishing returns. 32,000 is a common, well-tested middle ground — this is why vocab_size is the very first number everything else depends on.
A7: hidden_size | B7: ='7B Breakdown'!B6 | E7: This is the width of the vector every single token gets turned into, and STAYS AT, through the entire model — think of it as each token's "working memory" size. Every matrix in the model is built to take a hidden_size-wide input and hand back a hidden_size-wide (or intermediate_size-wide, for the FFN's internal step) output. Because this one number appears in almost every formula below (often squared, in W_Q/W_K/W_V/W_O), it has an outsized effect on total parameter count — doubling hidden_size roughly QUADRUPLES the attention parameter count per layer, not just doubles it.
A8: n_layers | B8: ='7B Breakdown'!B7 | E8: How many times the token's vector gets refined. Each layer does NOT change the vector's SHAPE (still hidden_size in, hidden_size out) — it refines the CONTENT, adding one more round of "look at other tokens, then update what I currently think." More layers means more sequential reasoning steps, at the direct cost of more parameters AND more sequential compute (unlike heads, layers CANNOT run in parallel with each other — layer 2 needs layer 1's finished output before it can start).
A9: n_heads | B9: ='7B Breakdown'!B8 | E9: Instead of one big attention computation over all 4,096 dimensions at once, the model splits into this many smaller, independent, PARALLEL attention computations. Why split at all, instead of one large head? A single attention pass can only learn one notion of "what's relevant to what" at a time. Splitting into heads lets different heads specialize — empirically, different heads DO learn different things (one might track subject-verb agreement, another might track which pronoun refers to which noun) — without any of them interfering with each other's math, since each head's slice of the vector is completely separate from every other head's slice.
A10: head_dim | B10: ='7B Breakdown'!B9 | E10: head_dim = hidden_size ÷ n_heads, exactly, with NO remainder allowed — that's a real, hard constraint on picking n_heads in the first place (it must divide hidden_size evenly, which is why you see round numbers like 32, 40, 64 for n_heads rather than arbitrary ones). This is how wide each individual head's private slice of the vector is: 128 numbers, in this model.
A11: intermediate_size | B11: ='7B Breakdown'!B10 | E11: The FFN's internal "scratch space" width — wider than hidden_size specifically because a wider space gives the network more room to compute new nonlinear features before compressing back down to hidden_size. This number is INDEPENDENT of hidden_size/layers/heads — it's its own separate design choice, though in practice it's picked as a consistent multiple of hidden_size (≈2.688× here — see the Notes & Caveats sheet for exactly why not the more "obvious" 4×).
A13: STEP 1 — TOKEN EMBEDDING (initial tokens → vectors)
A14: Stage | B14: Shape | C14: Formula | D14: Parameters | E14: Why
A15: Initial vocabulary (distinct tokens) | B15: ="["&$B$6&" tokens]" | C15: given, not computed | D15: =$B$6 | E15: Chosen by whoever trained the tokenizer, as its own separate step done BEFORE the model itself is ever trained — this number is an input to the model's design, not something the model computes or learns.
A16: X — one token's embedding (a lookup, NOT a matmul) | B16: ="[1 × "&$B$7&"]" | C16: row lookup from the table below | D16: 0 (no extra params — reuses the table) | E16: Technically, looking up a token's row from the embedding table IS mathematically a matrix multiply: multiply the table by a one-hot vector (all zeros except a single 1 at the token's ID) and you get exactly that token's row back — a weighted sum where every weight is 0 except one. It's implemented as a direct index/lookup instead of an actual multiply, purely because multiplying by a vector that's 31,999 zeros and one 1 would waste enormous compute for zero benefit. This is the ONE stage in the whole model that isn't dense matrix multiplication in practice, even though it's mathematically equivalent to one.
A17: Embedding table W_E | B17: ="["&$B$6&" × "&$B$7&"]" | C17: vocab × hidden | D17: =$B$6*$B$7 | E17: One full hidden_size-wide row for EVERY possible token — literally a lookup table, 32,000 entries deep, each entry 4,096 numbers wide. Before training, every one of these 131,072,000 numbers is random noise; training is precisely the process that shapes each row into a meaningful representation of what that token tends to mean in context.
A19: WORKED EXAMPLE — X × W_Q, real shape (this exact matmul happens 32 times below, once per layer)
A20: Term | B20: Shape | E20: Why
A21: X (one token's hidden vector, input to this layer) | B21: ="[1 × "&$B$7&"]" | E21: This is the vector for ONE token, at the moment it enters THIS particular layer. On layer 1 it comes straight from the embedding table above; on layer 2 onward, it's whatever the PREVIOUS layer output. Every layer re-uses the exact same hidden_size-wide "slot" for both its input and its output — that shape-preservation is exactly what lets 32 of these stack back-to-back with no dimension mismatch anywhere.
A22: × W_Q (learned query-projection matrix) | B22: ="["&$B$7&" × "&$B$7&"]" | E22: W_Q is a SQUARE matrix (hidden×hidden) by this architecture's design choice — it takes a hidden_size-wide input and returns a hidden_size-wide output. It doesn't HAVE to be square (some architectures shrink or grow the dimension here), but keeping it square means the "query space" has exactly the same capacity as the token's own representation space — no information is deliberately thrown away or padded at this step.
A23: → Q (this token's query vector) | B23: ="[1 × "&$B$7&"]" | E23: Matrix multiplication, concretely: each of the 4,096 output numbers in Q is the DOT PRODUCT of the full 4,096-number input X with one COLUMN of W_Q — 4,096 multiplications plus 4,095 additions, PER output number, repeated 4,096 times (once per output number). That's 4,096 × 4,096 total multiply operations for this one matrix — which is EXACTLY where the 16,777,216 parameter count below comes from: every one of those 4,096×4,096 positions in W_Q is one independent, learned number.
A24: Parameters contributed by W_Q alone | C24: hidden² | D24: =$B$7*$B$7 | E24: The "4×" you'll see in Step 2 below is Q, K, V, and O — four SEPARATE hidden×hidden matrices per layer, each learned completely independently, each contributing its own 16,777,216 parameters. They all share the identical SHAPE but hold completely different, independently-trained VALUES: W_Q learns to build "questions", W_K learns to build "answer keys" that queries get compared against, W_V learns to build "the actual content to retrieve" once a match is found, and W_O learns to recombine all 32 heads' mixed-together outputs back into one coherent vector.
A25: K, V, and O use the IDENTICAL shape/formula — X×W_K=K, X×W_V=V, (mixed heads)×W_O=output — 4 matrices per layer, each [hidden×hidden]. Real trained VALUES differ per layer/matrix; the SHAPE and PARAMETER COUNT are identical every time, which is exactly why the row-by-row sum below works.
A27: WORKED EXAMPLE — the FFN, and why it's 3 matrices (not 2, not 4)
A28: Term | B28: Shape | E28: Why
A29: h (this layer's post-attention vector, FFN's input) | B29: ="[1 × "&$B$7&"]" | E29: The FFN runs AFTER attention finishes and its residual has been added — same hidden_size shape as X was for attention, for the identical reason: every stage in a layer must take hidden_size in and hand back hidden_size out, so stages (and whole layers) can chain without a dimension mismatch.
A30: × W_gate (learned "how much to let through" matrix) | B30: ="["&$B$7&" × "&$B$11&"]" | E30: First of the FFN's two PARALLEL up-projections. W_gate expands h from hidden_size (4,096) up into the FFN's wider intermediate_size (11,008) "scratch space" — then gets passed through a SiLU/Swish nonlinearity, producing a per-feature signal roughly meaning "how open is this gate."
A31: × W_up (learned "what content" matrix, computed in parallel) | B31: ="["&$B$7&" × "&$B$11&"]" | E31: Second up-projection, SAME shape as W_gate but a completely separate, independently-learned matrix — no nonlinearity applied here, just a linear expansion. This is the actual "content" signal that the gate above will modulate.
A32: → SiLU(gate) ⊙ up (elementwise multiply — THIS is why 2 matrices, not 1) | B32: ="[1 × "&$B$11&"]" | E32: The "⊙" is an ELEMENTWISE multiply, not a matmul: each of the 11,008 numbers in the gated result is simply (SiLU(gate)[i] × up[i]) — same-position numbers multiplied together, nothing else. This is a GATING mechanism: the gate branch (put through SiLU, squashed toward 0 or passed through) decides how much of the up branch's content survives into the FFN's output, feature by feature. A single ordinary matmul-then-nonlinearity (what a classic 2-matrix GELU FFN does) has no way to let one learned signal modulate another this way — that extra expressive power is specifically what costs the 3rd matrix.
A33: × W_down (compress back down) | B33: ="["&$B$11&" × "&$B$7&"]" | E33: The third matrix: maps the 11,008-wide gated result back down to hidden_size (4,096) so it can be added back via the residual connection, same as attention's output was. This is the mirror image of gate/up's expansion — intermediate_size in, hidden_size out.
A34: Parameters: gate + up + down, all three | C34: 3 × hidden × intermediate | D34: =3*$B$7*$B$11 | E34: THE ANSWER TO "WHY 3×": it is not a multiplier on size, it is literally a COUNT of three separate, independently-learned [hidden×intermediate]-shaped matrices — W_gate, W_up, and W_down — each contributing hidden×intermediate parameters. A classic pre-SwiGLU FFN only needs 2 matrices (one up-projection through a plain nonlinearity, one down-projection) because it has no gating branch to compute separately; SwiGLU's elementwise gate-times-up step (previous row) is exactly the mechanism that requires the extra, 3rd matrix. This is also why intermediate_size is ≈2.688×hidden rather than the classic 4×hidden — see the Notes & Caveats sheet: 3 matrices at a smaller multiplier lands at roughly the SAME total parameter budget as 2 matrices at 4×.
A36: STEP 2 — ALL 32 LAYERS, ENUMERATED (every layer listed, nothing compressed as ×32)
A37: Layer # | B37: Attention (Q+K+V+O), 4×hidden² | C37: FFN (gate+up+down), 3×hidden×intermediate | D37: Layer total | E37: Why
A38: Layer 1 | B38: =4*$B$7*$B$7 | C38: =3*$B$7*$B$11 | D38: =B38+C38+2*$B$7 | E38: This row's two numbers (67,108,864 for attention, 135,266,304 for FFN) are the exact formulas worked out above, applied to THIS layer's own, independently-trained W_Q/W_K/W_V/W_O/W_gate/W_up/W_down matrices. Every one of the 32 layers has this IDENTICAL shape and IDENTICAL parameter count — but each layer's actual matrix VALUES are learned completely independently during training. That's why the total is trivially "32 × one_layer" arithmetically, while the model's actual behavior is NOT just repeating the same transformation 32 times — layer 2 is a different learned function from layer 1, applied to whatever layer 1 handed it.
A39: Layer 2 | B39: =4*$B$7*$B$7 | C39: =3*$B$7*$B$11 | D39: =B39+C39+2*$B$7 | E39: Same shape/formula as Layer 1 — see the explanation there. Only the trained VALUES differ between layers, never the shape or the parameter count.
A40: Layer 3 | B40: =4*$B$7*$B$7 | C40: =3*$B$7*$B$11 | D40: =B40+C40+2*$B$7 | E40: Same shape/formula as Layer 1 — see the explanation there. Only the trained VALUES differ between layers, never the shape or the parameter count.
A41: Layer 4 | B41: =4*$B$7*$B$7 | C41: =3*$B$7*$B$11 | D41: =B41+C41+2*$B$7 | E41: Same shape/formula as Layer 1 — see the explanation there. Only the trained VALUES differ between layers, never the shape or the parameter count.
A42: Layer 5 | B42: =4*$B$7*$B$7 | C42: =3*$B$7*$B$11 | D42: =B42+C42+2*$B$7 | E42: Same shape/formula as Layer 1 — see the explanation there. Only the trained VALUES differ between layers, never the shape or the parameter count.
A43: Layer 6 | B43: =4*$B$7*$B$7 | C43: =3*$B$7*$B$11 | D43: =B43+C43+2*$B$7 | E43: Same shape/formula as Layer 1 — see the explanation there. Only the trained VALUES differ between layers, never the shape or the parameter count.
A44: Layer 7 | B44: =4*$B$7*$B$7 | C44: =3*$B$7*$B$11 | D44: =B44+C44+2*$B$7 | E44: Same shape/formula as Layer 1 — see the explanation there. Only the trained VALUES differ between layers, never the shape or the parameter count.
A45: Layer 8 | B45: =4*$B$7*$B$7 | C45: =3*$B$7*$B$11 | D45: =B45+C45+2*$B$7 | E45: Same shape/formula as Layer 1 — see the explanation there. Only the trained VALUES differ between layers, never the shape or the parameter count.
...
